Workbook

Sheet Price list
B2: ='Paramètres'!C5
B3: PRICE LIST — COMMUNICATION, DIRECTION ARTISTIQUE & DESIGN
B4: ='Paramètres'!C6
B7: PRÉPARÉ POUR | H7: DATE | I7: VALIDITÉ
B8: ='Paramètres'!C7 | H8: ='Paramètres'!C8 | I8: ='Paramètres'!C9&" jours"
B10: NOS TAUX HORAIRES & JOURNALIERS | E10: ="1 j/h (jour/homme) = "&'Paramètres'!C10&" heures de travail"
B11: PROFIL | H11: € / HEURE HT | I11: € / JOUR HT
B12: ='Paramètres'!B17 | H12: ='Paramètres'!C17 | I12: ='Paramètres'!D17
B13: ='Paramètres'!B18 | H13: ='Paramètres'!C18 | I13: ='Paramètres'!D18
B14: ='Paramètres'!B19 | H14: ='Paramètres'!C19 | I14: ='Paramètres'!D19
B15: ='Paramètres'!B20 | H15: ='Paramètres'!C20 | I15: ='Paramètres'!D20
B16: ='Paramètres'!B21 | H16: ='Paramètres'!C21 | I16: ='Paramètres'!D21
B17: ='Paramètres'!B22 | H17: ='Paramètres'!C22 | I17: ='Paramètres'!D22
B18: ='Paramètres'!B23 | H18: ='Paramètres'!C23 | I18: ='Paramètres'!D23
B19: ='Paramètres'!B24 | H19: ='Paramètres'!C24 | I19: ='Paramètres'!D24
B20: ='Paramètres'!B25 | H20: ='Paramètres'!C25 | I20: ='Paramètres'!D25
B21: ='Paramètres'!B26 | H21: ='Paramètres'!C26 | I21: ='Paramètres'!D26
B22: ='Paramètres'!B27 | H22: ='Paramètres'!C27 | I22: ='Paramètres'!D27
B23: ='Paramètres'!B28 | H23: ='Paramètres'!C28 | I23: ='Paramètres'!D28
B24: ='Paramètres'!B29 | H24: ='Paramètres'!C29 | I24: ='Paramètres'!D29
B27: NOS PRESTATIONS | E27: Durées indicatives en heures et en jours/homme (j/h).
B28: RÉF. | C28: PRESTATION | D28: DÉTAIL / LIVRABLES | E28: UNITÉ | F28: HEURES | G28: J/H | H28: PRIX HT | I28: PRIX TVAC | K28: Profil (interne) | L28: Frais HT (interne) | M28: Taux (interne)
B30: 01 | C30: STRATÉGIE & DIRECTION ARTISTIQUE
B31: 01.01 | C31: Audit de communication & de marque | D31: Analyse de l'existant, concurrence, recommandations | E31: forfait | F31: 12 | G31: =IF(F31="","",F31/'Paramètres'!$C$10) | H31: =CEILING(N(F31)*M31+L31,'Paramètres'!$C$12) | I31: =H31*(1+'Paramètres'!$C$11) | K31: Directeur artistique | L31: 0 | M31: =IFERROR(INDEX('Paramètres'!$C$17:$C$29,MATCH(K31,'Paramètres'!$B$17:$B$29,0)),0)
B32: 01.02 | C32: Plateforme de marque | D32: Positionnement, valeurs, ton, cibles, messages clés | E32: forfait | F32: 24 | G32: =IF(F32="","",F32/'Paramètres'!$C$10) | H32: =CEILING(N(F32)*M32+L32,'Paramètres'!$C$12) | I32: =H32*(1+'Paramètres'!$C$11) | K32: Directeur artistique | L32: 0 | M32: =IFERROR(INDEX('Paramètres'!$C$17:$C$29,MATCH(K32,'Paramètres'!$B$17:$B$29,0)),0)
B33: 01.03 | C33: Stratégie de communication annuelle | D33: Plan d'actions, canaux, calendrier, budget | E33: forfait | F33: 24 | G33: =IF(F33="","",F33/'Paramètres'!$C$10) | H33: =CEILING(N(F33)*M33+L33,'Paramètres'!$C$12) | I33: =H33*(1+'Paramètres'!$C$11) | K33: Chef de projet | L33: 0 | M33: =IFERROR(INDEX('Paramètres'!$C$17:$C$29,MATCH(K33,'Paramètres'!$B$17:$B$29,0)),0)
B34: 01.04 | C34: Atelier créatif / brainstorming | D34: Séance de travail avec vos équipes (½ journée) | E34: forfait | F34: 4 | G34: =IF(F34="","",F34/'Paramètres'!$C$10) | H34: =CEILING(N(F34)*M34+L34,'Paramètres'!$C$12) | I34: =H34*(1+'Paramètres'!$C$11) | K34: Directeur artistique | L34: 0 | M34: =IFERROR(INDEX('Paramètres'!$C$17:$C$29,MATCH(K34,'Paramètres'!$B$17:$B$29,0)),0)
B35: 01.05 | C35: Moodboard & concept créatif | D35: Pistes visuelles et univers graphique | E35: forfait | F35: 8 | G35: =IF(F35="","",F35/'Paramètres'!$C$10) | H35: =CEILING(N(F35)*M35+L35,'Paramètres'!$C$12) | I35: =H35*(1+'Paramètres'!$C$11) | K35: Directeur artistique | L35: 0 | M35: =IFERROR(INDEX('Paramètres'!$C$17:$C$29,MATCH(K35,'Paramètres'!$B$17:$B$29,0)),0)
B36: 01.06 | C36: Direction artistique | D36: Supervision créative d'un projet | E36: heure | F36: 1 | G36: =IF(F36="","",F36/'Paramètres'!$C$10) | H36: =CEILING(N(F36)*M36+L36,'Paramètres'!$C$12) | I36: =H36*(1+'Paramètres'!$C$11) | K36: Directeur artistique | L36: 0 | M36: =IFERROR(INDEX('Paramètres'!$C$17:$C$29,MATCH(K36,'Paramètres'!$B$17:$B$29,0)),0)
B37: 01.07 | C37: Direction artistique — journée | D37: Présence shooting / tournage / production | E37: jour | F37: 8 | G37: =IF(F37="","",F37/'Paramètres'!$C$10) | H37: =CEILING(N(F37)*M37+L37,'Paramètres'!$C$12) | I37: =H37*(1+'Paramètres'!$C$11) | K37: Directeur artistique | L37: 0 | M37: =IFERROR(INDEX('Paramètres'!$C$17:$C$29,MATCH(K37,'Paramètres'!$B$17:$B$29,0)),0)
B38: 01.08 | C38: Gestion de projet | D38: Coordination, planning, suivi fournisseurs | E38: heure | F38: 1 | G38: =IF(F38="","",F38/'Paramètres'!$C$10) | H38: =CEILING(N(F38)*M38+L38,'Paramètres'!$C$12) | I38: =H38*(1+'Paramètres'!$C$11) | K38: Chef de projet | L38: 0 | M38: =IFERROR(INDEX('Paramètres'!$C$17:$C$29,MATCH(K38,'Paramètres'!$B$17:$B$29,0)),0)
B39: 01.09 | C39: Réunion client | D39: Rendez-vous de suivi, déplacement inclus (Belgique) | E39: forfait | F39: 2 | G39: =IF(F39="","",F39/'Paramètres'!$C$10) | H39: =CEILING(N(F39)*M39+L39,'Paramètres'!$C$12) | I39: =H39*(1+'Paramètres'!$C$11) | K39: Chef de projet | L39: 30 | M39: =IFERROR(INDEX('Paramètres'!$C$17:$C$29,MATCH(K39,'Paramètres'!$B$17:$B$29,0)),0)
B41: 02 | C41: IDENTITÉ VISUELLE & BRANDING
B42: 02.01 | C42: Création de logo | D42: 3 pistes créatives, 2 allers-retours, fichiers sources | E42: forfait | F42: 24 | G42: =IF(F42="","",F42/'Paramètres'!$C$10) | H42: =CEILING(N(F42)*M42+L42,'Paramètres'!$C$12) | I42: =H42*(1+'Paramètres'!$C$11) | K42: Graphiste | L42: 0 | M42: =IFERROR(INDEX('Paramètres'!$C$17:$C$29,MATCH(K42,'Paramètres'!$B$17:$B$29,0)),0)
B43: 02.02 | C43: Refonte / modernisation de logo | D43: Évolution d'un logo existant | E43: forfait | F43: 14 | G43: =IF(F43="","",F43/'Paramètres'!$C$10) | H43: =CEILING(N(F43)*M43+L43,'Paramètres'!$C$12) | I43: =H43*(1+'Paramètres'!$C$11) | K43: Graphiste | L43: 0 | M43: =IFERROR(INDEX('Paramètres'!$C$17:$C$29,MATCH(K43,'Paramètres'!$B$17:$B$29,0)),0)
B44: 02.03 | C44: Charte graphique | D44: Couleurs, typographies, règles d'usage (PDF) | E44: forfait | F44: 16 | G44: =IF(F44="","",F44/'Paramètres'!$C$10) | H44: =CEILING(N(F44)*M44+L44,'Paramètres'!$C$12) | I44: =H44*(1+'Paramètres'!$C$11) | K44: Graphiste | L44: 0 | M44: =IFERROR(INDEX('Paramètres'!$C$17:$C$29,MATCH(K44,'Paramètres'!$B$17:$B$29,0)),0)
B45: 02.04 | C45: Brandbook complet | D45: Charte + déclinaisons + exemples d'application | E45: forfait | F45: 32 | G45: =IF(F45="","",F45/'Paramètres'!$C$10) | H45: =CEILING(N(F45)*M45+L45,'Paramètres'!$C$12) | I45: =H45*(1+'Paramètres'!$C$11) | K45: Directeur artistique | L45: 0 | M45: =IFERROR(INDEX('Paramètres'!$C$17:$C$29,MATCH(K45,'Paramètres'!$B$17:$B$29,0)),0)
B46: 02.05 | C46: Naming | D46: Recherche de nom, 10 propositions argumentées | E46: forfait | F46: 12 | G46: =IF(F46="","",F46/'Paramètres'!$C$10) | H46: =CEILING(N(F46)*M46+L46,'Paramètres'!$C$12) | I46: =H46*(1+'Paramètres'!$C$11) | K46: Rédacteur / copywriter | L46: 0 | M46: =IFERROR(INDEX('Paramètres'!$C$17:$C$29,MATCH(K46,'Paramètres'!$B$17:$B$29,0)),0)
B47: 02.06 | C47: Slogan / signature de marque | D47: 5 propositions | E47: forfait | F47: 4 | G47: =IF(F47="","",F47/'Paramètres'!$C$10) | H47: =CEILING(N(F47)*M47+L47,'Paramètres'!$C$12) | I47: =H47*(1+'Paramètres'!$C$11) | K47: Rédacteur / copywriter | L47: 0 | M47: =IFERROR(INDEX('Paramètres'!$C$17:$C$29,MATCH(K47,'Paramètres'!$B$17:$B$29,0)),0)
B48: 02.07 | C48: Papeterie | D48: Carte de visite, papier en-tête, enveloppe | E48: forfait | F48: 6 | G48: =IF(F48="","",F48/'Paramètres'!$C$10) | H48: =CEILING(N(F48)*M48+L48,'Paramètres'!$C$12) | I48: =H48*(1+'Paramètres'!$C$11) | K48: Graphiste | L48: 0 | M48: =IFERROR(INDEX('Paramètres'!$C$17:$C$29,MATCH(K48,'Paramètres'!$B$17:$B$29,0)),0)
...

Sheet Paramètres
B2: PARAMÈTRES — usage interne
B3: Modifiez uniquement les cellules en bleu sur fond jaune. La price list se met à jour automatiquement.
B5: Nom de l'agence | C5: [NOM DE VOTRE AGENCE]
B6: Coordonnées agence | C6: [adresse · téléphone · e-mail · site web · n° TVA]
B7: Client | C7: Démarches SRL — concessionnaire Helicave
B8: Date de la price list | C8: 46288
B9: Validité de l'offre (jours) | C9: 90
B10: Heures par jour de travail (1 j/h) | C10: 8
B11: TVA | C11: 0.21 | D11: TVA belge 21 %. Mettre 0 % si non applicable.
B12: Arrondi des prix (€) | C12: 5 | D12: Les prix calculés sont arrondis au multiple supérieur (ex. 5 €).
B15: TAUX HORAIRES PAR PROFIL (HT)
B16: Profil | C16: Taux horaire HT | D16: Taux journalier HT
B17: Directeur artistique | C17: 85 | D17: =C17*$C$10
B18: Chef de projet | C18: 70 | D18: =C18*$C$10
B19: Graphiste | C19: 65 | D19: =C19*$C$10
B20: Illustrateur | C20: 65 | D20: =C20*$C$10
B21: Designer 3D | C21: 75 | D21: =C21*$C$10
B22: Photographe | C22: 70 | D22: =C22*$C$10
B23: Vidéaste | C23: 75 | D23: =C23*$C$10
B24: Monteur / motion designer | C24: 70 | D24: =C24*$C$10
B25: Pilote drone | C25: 85 | D25: =C25*$C$10
B26: Webdesigner UI/UX | C26: 70 | D26: =C26*$C$10
B27: Développeur web | C27: 70 | D27: =C27*$C$10
B28: Community manager | C28: 55 | D28: =C28*$C$10
B29: Rédacteur / copywriter | C29: 55 | D29: =C29*$C$10
B31: Taux indicatifs (fourchette moyenne d'une agence de communication en Belgique) — à remplacer par vos tarifs réels.
