Workbook

Sheet Price list
B2: ='Paramètres'!C5
B3: PRICE LIST — COMMUNICATION, DIRECTION ARTISTIQUE & DESIGN
B4: ='Paramètres'!C6
B7: PRÉPARÉ POUR | L7: DATE | M7: VALIDITÉ
B8: ='Paramètres'!C7 | L8: ='Paramètres'!C8 | M8: ='Paramètres'!C9&" jours"
B10: Cochez la colonne « VALIDÉ » pour chaque prestation retenue : le montant engagé et le cumul se calculent automatiquement.
B11: ="Durées indicatives en heures et en jours/homme (1 j/h = "&'Paramètres'!C10&" h). Prix HT, TVA "&TEXT('Paramètres'!C11,"0%")&"."
B13: RÉF. | C13: PRESTATION | D13: DÉTAIL / LIVRABLES | E13: UNITÉ | F13: HEURES | G13: J/H | H13: PRIX HT | I13: PRIX TTC | J13: QTÉ | K13: VALIDÉ | L13: MONTANT ENGAGÉ HT | M13: CUMUL ENGAGÉ HT
B15: 01 | C15: STRATÉGIE & DIRECTION ARTISTIQUE
B16: 01.01 | C16: Audit de communication & de marque | D16: Analyse de l'existant, concurrence, recommandations | E16: forfait | F16: 12 | G16: =IF(F16="","",F16/'Paramètres'!$C$10) | H16: 1224 | I16: =H16*(1+'Paramètres'!$C$11) | J16: 1 | K16: FALSE | L16: =IF(K16=TRUE,H16*J16,0) | M16: =SUM(L$14:L16)
B17: 01.02 | C17: Plateforme de marque | D17: Positionnement, valeurs, ton, cibles, messages clés | E17: forfait | F17: 24 | G17: =IF(F17="","",F17/'Paramètres'!$C$10) | H17: 2448 | I17: =H17*(1+'Paramètres'!$C$11) | J17: 1 | K17: FALSE | L17: =IF(K17=TRUE,H17*J17,0) | M17: =SUM(L$14:L17)
B18: 01.03 | C18: Stratégie de communication annuelle | D18: Plan d'actions, canaux, calendrier, budget | E18: forfait | F18: 24 | G18: =IF(F18="","",F18/'Paramètres'!$C$10) | H18: 2016 | I18: =H18*(1+'Paramètres'!$C$11) | J18: 1 | K18: FALSE | L18: =IF(K18=TRUE,H18*J18,0) | M18: =SUM(L$14:L18)
B19: 01.04 | C19: Atelier créatif / brainstorming | D19: Séance de travail avec vos équipes (½ journée) | E19: forfait | F19: 4 | G19: =IF(F19="","",F19/'Paramètres'!$C$10) | H19: 408 | I19: =H19*(1+'Paramètres'!$C$11) | J19: 1 | K19: FALSE | L19: =IF(K19=TRUE,H19*J19,0) | M19: =SUM(L$14:L19)
B20: 01.05 | C20: Moodboard & concept créatif | D20: Pistes visuelles et univers graphique | E20: forfait | F20: 8 | G20: =IF(F20="","",F20/'Paramètres'!$C$10) | H20: 816 | I20: =H20*(1+'Paramètres'!$C$11) | J20: 1 | K20: FALSE | L20: =IF(K20=TRUE,H20*J20,0) | M20: =SUM(L$14:L20)
B21: 01.06 | C21: Direction artistique | D21: Supervision créative d'un projet | E21: heure | F21: 1 | G21: =IF(F21="","",F21/'Paramètres'!$C$10) | H21: 102 | I21: =H21*(1+'Paramètres'!$C$11) | J21: 1 | K21: FALSE | L21: =IF(K21=TRUE,H21*J21,0) | M21: =SUM(L$14:L21)
B22: 01.07 | C22: Direction artistique — journée | D22: Présence shooting / tournage / production | E22: jour | F22: 8 | G22: =IF(F22="","",F22/'Paramètres'!$C$10) | H22: 816 | I22: =H22*(1+'Paramètres'!$C$11) | J22: 1 | K22: FALSE | L22: =IF(K22=TRUE,H22*J22,0) | M22: =SUM(L$14:L22)
B23: 01.08 | C23: Gestion de projet | D23: Coordination, planning, suivi fournisseurs | E23: heure | F23: 1 | G23: =IF(F23="","",F23/'Paramètres'!$C$10) | H23: 84 | I23: =H23*(1+'Paramètres'!$C$11) | J23: 1 | K23: FALSE | L23: =IF(K23=TRUE,H23*J23,0) | M23: =SUM(L$14:L23)
B24: 01.09 | C24: Réunion client | D24: Rendez-vous de suivi, déplacement local inclus | E24: forfait | F24: 2 | G24: =IF(F24="","",F24/'Paramètres'!$C$10) | H24: 204 | I24: =H24*(1+'Paramètres'!$C$11) | J24: 1 | K24: FALSE | L24: =IF(K24=TRUE,H24*J24,0) | M24: =SUM(L$14:L24)
B26: 02 | C26: IDENTITÉ VISUELLE & BRANDING
B27: 02.01 | C27: Création de logo | D27: 3 pistes créatives, 2 allers-retours, fichiers sources | E27: forfait | F27: 24 | G27: =IF(F27="","",F27/'Paramètres'!$C$10) | H27: 1872 | I27: =H27*(1+'Paramètres'!$C$11) | J27: 1 | K27: FALSE | L27: =IF(K27=TRUE,H27*J27,0) | M27: =SUM(L$14:L27)
B28: 02.02 | C28: Refonte / modernisation de logo | D28: Évolution d'un logo existant | E28: forfait | F28: 14 | G28: =IF(F28="","",F28/'Paramètres'!$C$10) | H28: 1092 | I28: =H28*(1+'Paramètres'!$C$11) | J28: 1 | K28: FALSE | L28: =IF(K28=TRUE,H28*J28,0) | M28: =SUM(L$14:L28)
B29: 02.03 | C29: Charte graphique | D29: Couleurs, typographies, règles d'usage (PDF) | E29: forfait | F29: 16 | G29: =IF(F29="","",F29/'Paramètres'!$C$10) | H29: 1248 | I29: =H29*(1+'Paramètres'!$C$11) | J29: 1 | K29: FALSE | L29: =IF(K29=TRUE,H29*J29,0) | M29: =SUM(L$14:L29)
B30: 02.04 | C30: Brandbook complet | D30: Charte + déclinaisons + exemples d'application | E30: forfait | F30: 32 | G30: =IF(F30="","",F30/'Paramètres'!$C$10) | H30: 3264 | I30: =H30*(1+'Paramètres'!$C$11) | J30: 1 | K30: FALSE | L30: =IF(K30=TRUE,H30*J30,0) | M30: =SUM(L$14:L30)
B31: 02.05 | C31: Naming | D31: Recherche de nom, 10 propositions argumentées | E31: forfait | F31: 12 | G31: =IF(F31="","",F31/'Paramètres'!$C$10) | H31: 792 | I31: =H31*(1+'Paramètres'!$C$11) | J31: 1 | K31: FALSE | L31: =IF(K31=TRUE,H31*J31,0) | M31: =SUM(L$14:L31)
B32: 02.06 | C32: Slogan / signature de marque | D32: 5 propositions | E32: forfait | F32: 4 | G32: =IF(F32="","",F32/'Paramètres'!$C$10) | H32: 264 | I32: =H32*(1+'Paramètres'!$C$11) | J32: 1 | K32: FALSE | L32: =IF(K32=TRUE,H32*J32,0) | M32: =SUM(L$14:L32)
B33: 02.07 | C33: Papeterie | D33: Carte de visite, papier en-tête, enveloppe | E33: forfait | F33: 6 | G33: =IF(F33="","",F33/'Paramètres'!$C$10) | H33: 468 | I33: =H33*(1+'Paramètres'!$C$11) | J33: 1 | K33: FALSE | L33: =IF(K33=TRUE,H33*J33,0) | M33: =SUM(L$14:L33)
B34: 02.08 | C34: Signature e-mail HTML | D34: Modèle aux couleurs de la marque | E34: forfait | F34: 2 | G34: =IF(F34="","",F34/'Paramètres'!$C$10) | H34: 156 | I34: =H34*(1+'Paramètres'!$C$11) | J34: 1 | K34: FALSE | L34: =IF(K34=TRUE,H34*J34,0) | M34: =SUM(L$14:L34)
B35: 02.09 | C35: Templates Office / PowerPoint | D35: Modèles Word + présentation | E35: forfait | F35: 8 | G35: =IF(F35="","",F35/'Paramètres'!$C$10) | H35: 624 | I35: =H35*(1+'Paramètres'!$C$11) | J35: 1 | K35: FALSE | L35: =IF(K35=TRUE,H35*J35,0) | M35: =SUM(L$14:L35)
B37: 03 | C37: GRAPHISME PRINT & ÉDITION
B38: 03.01 | C38: Heure de graphisme | D38: Création ou adaptation graphique | E38: heure | F38: 1 | G38: =IF(F38="","",F38/'Paramètres'!$C$10) | H38: 78 | I38: =H38*(1+'Paramètres'!$C$11) | J38: 1 | K38: FALSE | L38: =IF(K38=TRUE,H38*J38,0) | M38: =SUM(L$14:L38)
B39: 03.02 | C39: Journée de graphisme | D39: Journée de création (1 j/h) | E39: jour | F39: 8 | G39: =IF(F39="","",F39/'Paramètres'!$C$10) | H39: 624 | I39: =H39*(1+'Paramètres'!$C$11) | J39: 1 | K39: FALSE | L39: =IF(K39=TRUE,H39*J39,0) | M39: =SUM(L$14:L39)
B40: 03.03 | C40: Flyer A5 / A4 | D40: Recto-verso, fichiers prêts à imprimer | E40: forfait | F40: 4 | G40: =IF(F40="","",F40/'Paramètres'!$C$10) | H40: 312 | I40: =H40*(1+'Paramètres'!$C$11) | J40: 1 | K40: FALSE | L40: =IF(K40=TRUE,H40*J40,0) | M40: =SUM(L$14:L40)
B41: 03.04 | C41: Dépliant 3 volets | D41: Mise en page complète | E41: forfait | F41: 8 | G41: =IF(F41="","",F41/'Paramètres'!$C$10) | H41: 624 | I41: =H41*(1+'Paramètres'!$C$11) | J41: 1 | K41: FALSE | L41: =IF(K41=TRUE,H41*J41,0) | M41: =SUM(L$14:L41)
B42: 03.05 | C42: Brochure 8 pages | D42: Conception + mise en page | E42: forfait | F42: 16 | G42: =IF(F42="","",F42/'Paramètres'!$C$10) | H42: 1248 | I42: =H42*(1+'Paramètres'!$C$11) | J42: 1 | K42: FALSE | L42: =IF(K42=TRUE,H42*J42,0) | M42: =SUM(L$14:L42)
B43: 03.06 | C43: Catalogue / brochure — par page | D43: Mise en page, au-delà de 8 pages | E43: page | F43: 1.5 | G43: =IF(F43="","",F43/'Paramètres'!$C$10) | H43: 120 | I43: =H43*(1+'Paramètres'!$C$11) | J43: 1 | K43: FALSE | L43: =IF(K43=TRUE,H43*J43,0) | M43: =SUM(L$14:L43)
B44: 03.07 | C44: Affiche / poster | D44: Tout format | E44: forfait | F44: 4 | G44: =IF(F44="","",F44/'Paramètres'!$C$10) | H44: 312 | I44: =H44*(1+'Paramètres'!$C$11) | J44: 1 | K44: FALSE | L44: =IF(K44=TRUE,H44*J44,0) | M44: =SUM(L$14:L44)
B45: 03.08 | C45: Roll-up / kakémono | D45: Format standard 85 × 200 cm | E45: forfait | F45: 4 | G45: =IF(F45="","",F45/'Paramètres'!$C$10) | H45: 312 | I45: =H45*(1+'Paramètres'!$C$11) | J45: 1 | K45: FALSE | L45: =IF(K45=TRUE,H45*J45,0) | M45: =SUM(L$14:L45)
B46: 03.09 | C46: Bâche / banderole | D46: Grand format | E46: forfait | F46: 3 | G46: =IF(F46="","",F46/'Paramètres'!$C$10) | H46: 234 | I46: =H46*(1+'Paramètres'!$C$11) | J46: 1 | K46: FALSE | L46: =IF(K46=TRUE,H46*J46,0) | M46: =SUM(L$14:L46)
B47: 03.10 | C47: Annonce presse / magazine | D47: Création + déclinaisons formats | E47: forfait | F47: 3 | G47: =IF(F47="","",F47/'Paramètres'!$C$10) | H47: 234 | I47: =H47*(1+'Paramètres'!$C$11) | J47: 1 | K47: FALSE | L47: =IF(K47=TRUE,H47*J47,0) | M47: =SUM(L$14:L47)
B48: 03.11 | C48: Carton d'invitation | D48: Événement, portes ouvertes | E48: forfait | F48: 3 | G48: =IF(F48="","",F48/'Paramètres'!$C$10) | H48: 234 | I48: =H48*(1+'Paramètres'!$C$11) | J48: 1 | K48: FALSE | L48: =IF(K48=TRUE,H48*J48,0) | M48: =SUM(L$14:L48)
...

Sheet Paramètres
B2: PARAMÈTRES
B3: Cellules en bleu sur fond jaune = modifiables. La price list se met à jour automatiquement.
B5: Agence | C5: FABRIZIO VERRECCHIA — ABYSSE.LAB (18H22)
B6: Contact | C6: fab@18h22.com · SIRET 893 142 356 00037
B7: Client | C7: Démarches SRL — concessionnaire Helicave
B8: Date | C8: 46288
B9: Validité de l'offre (jours) | C9: 90
B10: Heures par jour (1 j/h) | C10: 8
B11: TVA | C11: 0.2 | D11: TVA française 20 %. Client belge assujetti : mettre 0 % (autoliquidation, art. 283-2 CGI).
